<?xml version="1.0"?>

<robot name="Robot_snake_sim">

  <material name="blue">
    <color rgba="0 0 0.8 1"/>
  </material>
  <material name="black">
    <color rgba="0 0 0 1"/>
  </material>
  <material name="white">
    <color rgba="1 1 1 1"/>
  </material>
    <material name="red">
    <color rgba="1 0 0 1"/>
  </material>


  <link name="base_link" >
      <visual>
      <geometry>
        <box size="0.1 0.6 0.6"/>
      </geometry>
      <material name="black"/>
    </visual>
    <collision>
      <geometry>
        <box size="0.1 0.6 0.6"/>
      </geometry>
    </collision>
    <inertial>
      <origin xyz="0 0 0" rpy="0 0 0"/>
      <mass value="1.0" />
      <inertia ixx="0.0741666666667" ixy="0.0" ixz="0.0" iyy="0.0585416666667" iyz="0.0" izz="0.0260416666667"/>
   </inertial>
  </link>
  
  <link name="link2" >
      <visual>
      <geometry>
        <cylinder length="0.12" radius="0.0475"/>
      </geometry>
     <origin rpy="0 1.57079632679 0" xyz="0.08 0 0"/>
      <material name="red"/>
    </visual>
    <collision>
      <geometry>
        <cylinder length="0.12" radius="0.0475"/>
      </geometry>
    </collision>
<inertial>
      <origin xyz="0 0 0" rpy="0 0 0"/>
      <mass value="1.0" />
      <inertia ixx="0.0741666666667" ixy="0.0" ixz="0.0" iyy="0.0585416666667" iyz="0.0" izz="0.0260416666667"/>
</inertial>
  </link>
  
  <link name="link3" >
      <visual>
      <geometry>
        <cylinder length="0.12" radius="0.0475"/>
      </geometry>
      <origin rpy="0 1.57079632679 0" xyz="0.08 0 0"/>
      <material name="white"/>
    </visual>
    <collision>
      <geometry>
        <cylinder length="0.12" radius="0.0475"/>
      </geometry>
    </collision>
<inertial>
      <origin xyz="0 0 0" rpy="0 0 0"/>
      <mass value="1.0" />
      <inertia ixx="0.0741666666667" ixy="0.0" ixz="0.0" iyy="0.0585416666667" iyz="0.0" izz="0.0260416666667"/>
</inertial>
  </link>
  
  <link name="link4" >
      <visual>
      <geometry>
        <cylinder length="0.12" radius="0.0475"/>
      </geometry>
      <origin rpy="0 1.57079632679 0" xyz="0.08 0 0"/>
      <material name="blue"/>
    </visual>
    <collision>
      <geometry>
        <cylinder length="0.12" radius="0.0475"/>
      </geometry>
    </collision>
    <inertial>
      <origin xyz="0 0 0" rpy="0 0 0"/>
      <mass value="1.0" />
      <inertia ixx="0.0741666666667" ixy="0.0" ixz="0.0" iyy="0.0585416666667" iyz="0.0" izz="0.0260416666667"/>
   </inertial>
  </link>

  <link name="link5" >
      <visual>
      <geometry>
        <cylinder length="0.12" radius="0.0475"/>
      </geometry>
      <origin rpy="0 1.57079632679 0" xyz="0.08 0 0"/>
      <material name="white"/>
    </visual>
    <collision>
      <geometry>
        <cylinder length="0.12" radius="0.0475"/>
      </geometry>
    </collision>
<inertial>
      <origin xyz="0 0 0" rpy="0 0 0"/>
      <mass value="1.0" />
      <inertia ixx="0.0741666666667" ixy="0.0" ixz="0.0" iyy="0.0585416666667" iyz="0.0" izz="0.0260416666667"/>
</inertial>
  </link>

  <link name="link6" >
      <visual>
      <geometry>
        <cylinder length="0.12" radius="0.0475"/>
      </geometry>
      <origin rpy="0 1.57079632679 0" xyz="0.08 0 0"/>
      <material name="blue"/>
    </visual>
    <collision>
      <geometry>
        <cylinder length="0.12" radius="0.0475"/>
      </geometry>
    </collision>
<inertial>
      <origin xyz="0 0 0" rpy="0 0 0"/>
      <mass value="1.0" />
      <inertia ixx="0.0741666666667" ixy="0.0" ixz="0.0" iyy="0.0585416666667" iyz="0.0" izz="0.0260416666667"/>
</inertial>
  </link>

  <link name="link7" >
      <visual>
      <geometry>
        <cylinder length="0.12" radius="0.0475"/>
      </geometry>
      <origin rpy="0 1.57079632679 0" xyz="0.08 0 0"/>
      <material name="white"/>
    </visual>
    <collision>
      <geometry>
        <cylinder length="0.12" radius="0.0475"/>
      </geometry>
    </collision>
<inertial>
      <origin xyz="0 0 0" rpy="0 0 0"/>
      <mass value="1.0" />
      <inertia ixx="0.0741666666667" ixy="0.0" ixz="0.0" iyy="0.0585416666667" iyz="0.0" izz="0.0260416666667"/>
</inertial>
  </link>

  <link name="link8" >
      <visual>
      <geometry>
        <cylinder length="0.12" radius="0.0475"/>
      </geometry>
      <origin rpy="0 1.57079632679 0" xyz="0.08 0 0"/>
      <material name="blue"/>
    </visual>
    <collision>
      <geometry>
        <cylinder length="0.12" radius="0.0475"/>
      </geometry>
    </collision>
<inertial>
      <origin xyz="0 0 0" rpy="0 0 0"/>
      <mass value="1.0" />
      <inertia ixx="0.0741666666667" ixy="0.0" ixz="0.0" iyy="0.0585416666667" iyz="0.0" izz="0.0260416666667"/>
</inertial>
  </link>



  <joint name="joint1" type="prismatic">
    <parent link="base_link"/>
    <child link="link2"/>
    <limit effort="1000.0" lower="0" upper="2" velocity="0.5"/>
    <axis xyz="1 0 0" />
    <origin xyz="0 0 0" rpy="0 0 0" />
  </joint>

  <joint name="joint2" type="continuous">
    <parent link="link2"/>
    <child link="link3"/>
    <origin xyz="0.16 0 0" rpy="0 0 0" />
    <axis xyz="0 0 1" />
  </joint>

  <joint name="joint3" type="continuous">
    <parent link="link3"/>
    <child link="link4"/>
    <origin xyz="0.16 0 0" rpy="0 0 0" />
    <axis xyz="0 1 0" />
  </joint>

  <joint name="joint4" type="continuous">
    <parent link="link4"/>
    <child link="link5"/>
    <origin xyz="0.16 0 0" rpy="0 0 0" />
    <axis xyz="0 0 1" />
  </joint>

  <joint name="joint5" type="continuous">
    <parent link="link5"/>
    <child link="link6"/>
    <origin xyz="0.16 0 0" rpy="0 0 0" />
    <axis xyz="0 1 0" />
  </joint>

  <joint name="joint6" type="continuous">
    <parent link="link6"/>
    <child link="link7"/>
    <origin xyz="0.16 0 0" rpy="0 0 0" />
    <axis xyz="0 0 1" />
  </joint>
  <joint name="joint7" type="continuous">
    <parent link="link7"/>
    <child link="link8"/>
    <origin xyz="0.16 0 0" rpy="0 0 0" />
    <axis xyz="0 1 0" />
  </joint>
  
  
<gazebo reference="base_link">
<material>Gazebo/White</material>
</gazebo>
<gazebo reference="link2">
<material>Gazebo/White</material>
</gazebo>
<gazebo reference="link3">
<material>Gazebo/White</material>
</gazebo>
<gazebo reference="link4">
<material>Gazebo/White</material>
</gazebo>
<gazebo reference="link5">
<material>Gazebo/White</material>
</gazebo>
<gazebo reference="link6">
<material>Gazebo/White</material>
</gazebo>
<gazebo reference="link7">
<material>Gazebo/White</material>
</gazebo>
<gazebo reference="link8">
<material>Gazebo/White</material>
</gazebo>

  <!-- ros_control plugin -->
  <gazebo>
    <plugin name="gazebo_ros_control" filename="libgazebo_ros_control.so">
      <robotNamespace>/shmulik</robotNamespace>
    </plugin>
  </gazebo>

</robot>


