<?xml version="1.0"?>
<robot name="snake_10" xmlns:xacro="http://www.ros.org/wiki/xacro">

  <!-- properties -->
  <!-- 1.57079632679 -->
  <property name="cyl_radius" value="0.0475" /> 
  <property name="cyl_height" value="0.12" />
  <property name="cyl_mass" value="0.125" /> <!-- in kg-->
  <property name="rev_axisY" value="0 1 0" />
  <property name="rev_axisZ" value="0 0 1" />
  <property name="deg_to_rad" value="0.01745329251994329577"/>
  <property name="Deg90toRad" value="1.57079632679"/>

  <macro name="cylinder_inertia" params="mass">
	<!--<origin xyz="0 0 ${cyl_radius}" rpy="0 0 0"/>-->
  <origin xyz="0 0 0" rpy="0 0 0"/>
    <inertia ixx="0.0741666666667" ixy="0.0" ixz="0.0" iyy="0.0585416666667" iyz="0.0" izz="0.0260416666667"/>
  </macro>


  <material name="blue">
    <color rgba="0 0 0.8 1"/>
  </material>
  <material name="black">
    <color rgba="0 0 0 1"/>
  </material>
  <material name="white">
    <color rgba="1 1 1 1"/>
  </material>
    <material name="red">
    <color rgba="1 0 0 1"/>
  </material>

  <xacro:macro name="transmission_block" params="joint_name">
	  <transmission name="tran1">
	    <type>transmission_interface/SimpleTransmission</type>
	    <joint name="${joint_name}">
	      <hardwareInterface>hardware_interface/PositionJointInterface</hardwareInterface>
	    </joint>
	    <actuator name="motor_${joint_name}">
	      <hardwareInterface>hardware_interface/PositionJointInterface</hardwareInterface>
	      <mechanicalReduction>1</mechanicalReduction>
	    </actuator>
	  </transmission>
   </xacro:macro>

 
<xacro:macro name="cyl" params="num material">  
     <!-- params : number color revAxis { Y , Z } -->        
    <link name="link${num}">
      <visual>
        <origin rpy="0 0 ${Deg90toRad}" xyz="0.136 ${-cyl_radius} -0.0525"/>
        <geometry>
          <!--<cylinder length="${cyl_height}" radius="${cyl_radius}" />-->
          <mesh filename="package://robot_snake_1/meshes/link_2.STL"/>
        </geometry>
        <material name="${material}" />
      </visual>

      <collision>
        <origin rpy="0 0 1.57079632679" xyz="0.136 ${-cyl_radius} -0.0525"/>
        <geometry>
          <!--<cylinder length="${cyl_height}" radius="${cyl_radius}" />-->
          <mesh filename="package://robot_snake_1/meshes/link_2.STL"/>
        </geometry>
      </collision>
      <inertial>
        <mass value="${cyl_mass}" />
        <cylinder_inertia  mass="${cyl_mass}" />
      </inertial>
    </link>
    
  </xacro:macro>
 
 <xacro:macro name="attachjoint" params="parent child rev">
  <joint name="joint${child}" type="continuous">
    <parent link="link${parent}"/>
    <child link="link${child}"/>
    <origin xyz="0.16 0 0" rpy="0 0 0" />
    <axis xyz="${rev}" />
    <dynamics damping="0.7"/>
  </joint>
 </xacro:macro>
 
 
<link name="dummy">
</link>

<link name="base_link" >
  <visual>
    <origin rpy="1.57079632679 0 3.14159265359" xyz="1 -0.5 -0.36"/> 
    <geometry>
        <!--<box size="0.1 0.6 0.6"/>-->
      <mesh filename="package://robot_snake_1/meshes/base.STL"/>
    </geometry>
  </visual>
  <collision>
    <geometry>
      <box size="2 1 0.72"/>
    </geometry>
  </collision>
  <inertial>
    <origin xyz="0 0 0" rpy="0 0 0"/>
    <mass value="100000" />
    <inertia ixx="100000" ixy="0.0" ixz="0.0" iyy="100000" iyz="0.0" izz="100000"/>
  </inertial>
</link>

    <link name="arc" >
      <visual>
        <origin rpy="0 0 0" xyz="-0.6 -0.195 -0.3175"/><!---0.3175-->
        <geometry>
        <!--<box size="0.3 0.3 0.3"/>-->
          <mesh filename="package://robot_snake_1/meshes/arc.STL"/>
        </geometry>
      </visual>
    <collision>
    <origin rpy="0 0 0" xyz="0 0 0"/>
      <geometry>
        <box size="1.2 0.3 0.3"/><!--0.495-->
      </geometry>
    </collision>
    <inertial>
      <origin xyz="0 0 0" rpy="0 0 0"/>
      <mass value="0.2" />
      <inertia ixx="0.0741666666667" ixy="0.0" ixz="0.0" iyy="0.0585416666667" iyz="0.0" izz="0.0260416666667"/>
   </inertial>
  </link>
 

<cyl num="1"  material="blue" /> 
<cyl num="2"  material="white" />
<cyl num="3"  material="blue" />
<cyl num="4"  material="white"/>
<cyl num="5"  material="blue" />
<cyl num="6"  material="white" />
<cyl num="7"  material="blue" />
<cyl num="8"  material="white" />
<cyl num="9"  material="blue" />
<cyl num="10" material="white" />


  <joint name="dummy_joint" type="fixed">
    <parent link="dummy" />
    <child link="base_link" />
  </joint>
  
  <joint name="linear1" type="prismatic">
    <parent link="base_link"/>
    <child link="arc"/>
    <limit effort="0" lower="0" upper="2" velocity="0.5"/>
    <axis xyz="1 0 0" />
    <origin xyz="-0.5 0 ${0.7365-0.03175}" rpy="0 0 0" />
        <dynamics damping="0.7"/>
  </joint>
  
  <joint name="joint1" type="continuous">
    <parent link="arc"/>
    <child link="link1"/>
    <origin xyz="${0.6+0.048} 0 0" rpy="0 0 0" /><!--0.0525 -->
    <axis xyz="0 0 1" />
    <dynamics damping="0.7"/>
  </joint>

<attachjoint parent="1"  child="2" rev="0 0 1" />
<attachjoint parent="2"  child="3" rev="0 0 1" />
<attachjoint parent="3"  child="4" rev="0 0 1" />
<attachjoint parent="4"  child="5" rev="0 0 1" />
<attachjoint parent="5"  child="6" rev="0 0 1" />
<attachjoint parent="6"  child="7" rev="0 0 1" />
<attachjoint parent="7"  child="8" rev="0 0 1" />
<attachjoint parent="8"  child="9" rev="0 0 1" />
<attachjoint parent="9"  child="10" rev="0 0 1" />

<gazebo reference="base_link">
<material>Gazebo/Gray</material>
</gazebo>
<gazebo reference="arc">
<material>Gazebo/Orange</material>
</gazebo>
<gazebo reference="link1">
<material>Gazebo/White</material>
</gazebo>
<gazebo reference="link2">
<material>Gazebo/Blue</material>
</gazebo>
<gazebo reference="link3">
<material>Gazebo/White</material>
</gazebo>
<gazebo reference="link4">
<material>Gazebo/Blue</material>
</gazebo>
<gazebo reference="link5">
<material>Gazebo/White</material>
</gazebo>
<gazebo reference="link6">
<material>Gazebo/Blue</material>
</gazebo>
<gazebo reference="link7">
<material>Gazebo/White</material>
</gazebo>
<gazebo reference="link8">
<material>Gazebo/Blue</material>
</gazebo>
<gazebo reference="link9">
<material>Gazebo/White</material>
</gazebo>
<gazebo reference="link10">
<material>Gazebo/Blue</material>
</gazebo>


<!-- ///////////////////////////////////////////////////////////////////////////////////////////////////////////////////// -->
  <!-- Transmissions for ROS Control -->
<transmission name="linear1">
  <type>transmission_interface/SimpleTransmission</type>
  <joint name="linear1">
    <hardwareInterface>hardware_interface/PositionJointInterface</hardwareInterface>
  </joint>
  <actuator name="motor_0">
	  <hardwareInterface>hardware_interface/PositionJointInterface</hardwareInterface>
	  <mechanicalReduction>1</mechanicalReduction>
	</actuator>
</transmission>

   <xacro:transmission_block joint_name="joint1"/>
   <xacro:transmission_block joint_name="joint2"/>
   <xacro:transmission_block joint_name="joint3"/>
   <xacro:transmission_block joint_name="joint4"/>
   <xacro:transmission_block joint_name="joint5"/>
   <xacro:transmission_block joint_name="joint6"/>
   <xacro:transmission_block joint_name="joint7"/>  
   <xacro:transmission_block joint_name="joint8"/>
   <xacro:transmission_block joint_name="joint9"/>
   <xacro:transmission_block joint_name="joint10"/>


  <!-- ros_control plugin -->
  <gazebo>
    <plugin name="gazebo_ros_control" filename="libgazebo_ros_control.so">
      <robotNamespace>/snake_10</robotNamespace>
      <legacyModeNS>true</legacyModeNS>
    </plugin>
  </gazebo>
<!--
    <xacro:include filename="$(find mastering_ros_robot_description_pkg)/urdf/sensors/xtion_pro_live.urdf.xacro"/>
    -->
  <!-- Define RGB-D sensor -->
  <!--
  <xacro:xtion_pro_live name="rgbd_camera" parent="link10">
   <origin xyz="0.2 0 0" rpy="0 0 0"/>
    <origin xyz="0 0 0" rpy="${-90.0 * deg_to_rad} 0 ${-90.0 * deg_to_rad}"/>
  </xacro:xtion_pro_live>
  -->
</robot>
